[2023-04-30T21:37:48.427+0000] {taskinstance.py:1083} INFO - Dependencies all met for <TaskInstance: basic_etl_dag.transform_task manual__2023-04-30T21:37:39.173828+00:00 [queued]>
[2023-04-30T21:37:48.439+0000] {taskinstance.py:1083} INFO - Dependencies all met for <TaskInstance: basic_etl_dag.transform_task manual__2023-04-30T21:37:39.173828+00:00 [queued]>
[2023-04-30T21:37:48.440+0000] {taskinstance.py:1279} INFO - 
--------------------------------------------------------------------------------
[2023-04-30T21:37:48.441+0000] {taskinstance.py:1280} INFO - Starting attempt 1 of 1
[2023-04-30T21:37:48.441+0000] {taskinstance.py:1281} INFO - 
--------------------------------------------------------------------------------
[2023-04-30T21:37:48.479+0000] {taskinstance.py:1300} INFO - Executing <Task(PythonOperator): transform_task> on 2023-04-30 21:37:39.173828+00:00
[2023-04-30T21:37:48.483+0000] {standard_task_runner.py:55} INFO - Started process 29581 to run task
[2023-04-30T21:37:48.489+0000] {standard_task_runner.py:82} INFO - Running: ['airflow', 'tasks', 'run', 'basic_etl_dag', 'transform_task', 'manual__2023-04-30T21:37:39.173828+00:00', '--job-id', '3', '--raw', '--subdir', 'DAGS_FOLDER/etl_dag.py', '--cfg-path', '/tmp/tmpsxpu1f46']
[2023-04-30T21:37:48.491+0000] {standard_task_runner.py:83} INFO - Job 3: Subtask transform_task
[2023-04-30T21:37:48.579+0000] {task_command.py:388} INFO - Running <TaskInstance: basic_etl_dag.transform_task manual__2023-04-30T21:37:39.173828+00:00 [running]> on host codespaces-f747d3
[2023-04-30T21:37:48.796+0000] {taskinstance.py:1507} INFO - Exporting the following env vars:
AIRFLOW_CTX_DAG_OWNER=airflow
AIRFLOW_CTX_DAG_ID=basic_etl_dag
AIRFLOW_CTX_TASK_ID=transform_task
AIRFLOW_CTX_EXECUTION_DATE=2023-04-30T21:37:39.173828+00:00
AIRFLOW_CTX_TRY_NUMBER=1
AIRFLOW_CTX_DAG_RUN_ID=manual__2023-04-30T21:37:39.173828+00:00
[2023-04-30T21:37:48.802+0000] {taskinstance.py:1768} ERROR - Task failed with exception
Traceback (most recent call last):
  File "/usr/local/python/3.10.4/lib/python3.10/site-packages/airflow/operators/python.py", line 175, in execute
    return_value = self.execute_callable()
  File "/usr/local/python/3.10.4/lib/python3.10/site-packages/airflow/operators/python.py", line 192, in execute_callable
    return self.python_callable(*self.op_args, **self.op_kwargs)
  File "/workspaces/airflow_etl/airflow/dags/etl_dag.py", line 25, in transform_data
    group_df = df3.columns = ['Count']
NameError: name 'df3' is not defined. Did you mean: 'df'?
[2023-04-30T21:37:48.813+0000] {taskinstance.py:1318} INFO - Marking task as FAILED. dag_id=basic_etl_dag, task_id=transform_task, execution_date=20230430T213739, start_date=20230430T213748, end_date=20230430T213748
[2023-04-30T21:37:48.851+0000] {standard_task_runner.py:100} ERROR - Failed to execute job 3 for task transform_task (name 'df3' is not defined; 29581)
[2023-04-30T21:37:48.900+0000] {local_task_job.py:208} INFO - Task exited with return code 1
[2023-04-30T21:37:48.918+0000] {taskinstance.py:2578} INFO - 0 downstream tasks scheduled from follow-on schedule check
